<?xml version="1.0"?>
<robot name="shipen_4dof">
  <material name="robot_gray">
    <color rgba="0.85 0.85 0.85 1.0"/>
  </material>
  <material name="robot_black">
    <color rgba="0.12 0.12 0.12 1.0"/>
  </material>
  <link name="base_link">
    <inertial>
      <origin xyz="0 0 0" rpy="0 0 0"/>
      <mass value="20.000000"/>
      <inertia ixx="0.001" ixy="0" ixz="0" iyy="0.001" iyz="0" izz="0.001"/>
    </inertial>
    <visual>
      <origin xyz="0 0 0" rpy="0 0 0"/>
      <geometry>
        <mesh filename="meshes/base_link/3d66-Editable_mesh-23002546-008.obj"/>
      </geometry>
      <material name="robot_gray">
        <color rgba="0.85 0.85 0.85 1.0"/>
      </material>
    </visual>
    <visual>
      <origin xyz="0 0 0" rpy="0 0 0"/>
      <geometry>
        <mesh filename="meshes/base_link/3d66-Editable_mesh-23002546-009.obj"/>
      </geometry>
      <material name="robot_gray">
        <color rgba="0.85 0.85 0.85 1.0"/>
      </material>
    </visual>
    <visual>
      <origin xyz="0 0 0" rpy="0 0 0"/>
      <geometry>
        <mesh filename="meshes/base_link/3d66-Editable_mesh-23002546-010.obj"/>
      </geometry>
      <material name="robot_gray">
        <color rgba="0.85 0.85 0.85 1.0"/>
      </material>
    </visual>
    <visual>
      <origin xyz="0 0 0" rpy="0 0 0"/>
      <geometry>
        <mesh filename="meshes/base_link/3d66-Editable_mesh-23002546-014.obj"/>
      </geometry>
      <material name="robot_gray">
        <color rgba="0.85 0.85 0.85 1.0"/>
      </material>
    </visual>
    <visual>
      <origin xyz="0 0 0" rpy="0 0 0"/>
      <geometry>
        <mesh filename="meshes/base_link/3d66-Editable_mesh-23002546-015.obj"/>
      </geometry>
      <material name="robot_gray">
        <color rgba="0.85 0.85 0.85 1.0"/>
      </material>
    </visual>
    <visual>
      <origin xyz="0 0 0" rpy="0 0 0"/>
      <geometry>
        <mesh filename="meshes/base_link/3d66-Editable_mesh-23002546-016.obj"/>
      </geometry>
      <material name="robot_gray">
        <color rgba="0.85 0.85 0.85 1.0"/>
      </material>
    </visual>
    <visual>
      <origin xyz="0 0 0" rpy="0 0 0"/>
      <geometry>
        <mesh filename="meshes/base_link/3d66-Editable_mesh-23002546-017.obj"/>
      </geometry>
      <material name="robot_gray">
        <color rgba="0.85 0.85 0.85 1.0"/>
      </material>
    </visual>
    <visual>
      <origin xyz="0 0 0" rpy="0 0 0"/>
      <geometry>
        <mesh filename="meshes/base_link/3d66-Editable_Poly-23002546-025.obj"/>
      </geometry>
      <material name="robot_gray">
        <color rgba="0.85 0.85 0.85 1.0"/>
      </material>
    </visual>
    <visual>
      <origin xyz="0 0 0" rpy="0 0 0"/>
      <geometry>
        <mesh filename="meshes/base_link/3d66-Editable_Poly-23002546-027.obj"/>
      </geometry>
      <material name="robot_gray">
        <color rgba="0.85 0.85 0.85 1.0"/>
      </material>
    </visual>
    <visual>
      <origin xyz="0 0 0" rpy="0 0 0"/>
      <geometry>
        <mesh filename="meshes/base_link/3d66-Editable_Poly-23002546-028.obj"/>
      </geometry>
      <material name="robot_gray">
        <color rgba="0.85 0.85 0.85 1.0"/>
      </material>
    </visual>
    <visual>
      <origin xyz="0 0 0" rpy="0 0 0"/>
      <geometry>
        <mesh filename="meshes/base_link/3d66-Editable_Poly-23002546-029.obj"/>
      </geometry>
      <material name="robot_gray">
        <color rgba="0.85 0.85 0.85 1.0"/>
      </material>
    </visual>
    <visual>
      <origin xyz="0 0 0" rpy="0 0 0"/>
      <geometry>
        <mesh filename="meshes/base_link/3d66-Editable_Poly-23002546-031.obj"/>
      </geometry>
      <material name="robot_gray">
        <color rgba="0.85 0.85 0.85 1.0"/>
      </material>
    </visual>
    <visual>
      <origin xyz="0 0 0" rpy="0 0 0"/>
      <geometry>
        <mesh filename="meshes/base_link/3d66-Editable_Poly-23002546-032.obj"/>
      </geometry>
      <material name="robot_gray">
        <color rgba="0.85 0.85 0.85 1.0"/>
      </material>
    </visual>
    <visual>
      <origin xyz="0 0 0" rpy="0 0 0"/>
      <geometry>
        <mesh filename="meshes/base_link/3d66-Editable_Poly-23002546-034.obj"/>
      </geometry>
      <material name="robot_gray">
        <color rgba="0.85 0.85 0.85 1.0"/>
      </material>
    </visual>
    <visual>
      <origin xyz="0 0 0" rpy="0 0 0"/>
      <geometry>
        <mesh filename="meshes/base_link/3d66-Editable_Poly-23002546-035.obj"/>
      </geometry>
      <material name="robot_gray">
        <color rgba="0.85 0.85 0.85 1.0"/>
      </material>
    </visual>
    <visual>
      <origin xyz="0 0 0" rpy="0 0 0"/>
      <geometry>
        <mesh filename="meshes/base_link/3d66-Editable_Poly-23002546-037.obj"/>
      </geometry>
      <material name="robot_gray">
        <color rgba="0.85 0.85 0.85 1.0"/>
      </material>
    </visual>
    <visual>
      <origin xyz="0 0 0" rpy="0 0 0"/>
      <geometry>
        <mesh filename="meshes/base_link/3d66-Editable_Poly-23002546-038.obj"/>
      </geometry>
      <material name="robot_gray">
        <color rgba="0.85 0.85 0.85 1.0"/>
      </material>
    </visual>
    <visual>
      <origin xyz="0 0 0" rpy="0 0 0"/>
      <geometry>
        <mesh filename="meshes/base_link/3d66-Editable_Poly-23002546-039.obj"/>
      </geometry>
      <material name="robot_gray">
        <color rgba="0.85 0.85 0.85 1.0"/>
      </material>
    </visual>
    <visual>
      <origin xyz="0 0 0" rpy="0 0 0"/>
      <geometry>
        <mesh filename="meshes/base_link/3d66-Editable_Poly-23002546-040.obj"/>
      </geometry>
      <material name="robot_gray">
        <color rgba="0.85 0.85 0.85 1.0"/>
      </material>
    </visual>
    <visual>
      <origin xyz="0 0 0" rpy="0 0 0"/>
      <geometry>
        <mesh filename="meshes/base_link/3d66-Editable_Poly-23002546-041.obj"/>
      </geometry>
      <material name="robot_gray">
        <color rgba="0.85 0.85 0.85 1.0"/>
      </material>
    </visual>
    <visual>
      <origin xyz="0 0 0" rpy="0 0 0"/>
      <geometry>
        <mesh filename="meshes/base_link/3d66-Editable_Poly-23002546-042.obj"/>
      </geometry>
      <material name="robot_gray">
        <color rgba="0.85 0.85 0.85 1.0"/>
      </material>
    </visual>
    <visual>
      <origin xyz="0 0 0" rpy="0 0 0"/>
      <geometry>
        <mesh filename="meshes/base_link/3d66-Editable_Poly-23002546-043.obj"/>
      </geometry>
      <material name="robot_gray">
        <color rgba="0.85 0.85 0.85 1.0"/>
      </material>
    </visual>
    <visual>
      <origin xyz="0 0 0" rpy="0 0 0"/>
      <geometry>
        <mesh filename="meshes/base_link/3d66-Editable_Poly-23002546-053.obj"/>
      </geometry>
      <material name="robot_gray">
        <color rgba="0.85 0.85 0.85 1.0"/>
      </material>
    </visual>
    <visual>
      <origin xyz="0 0 0" rpy="0 0 0"/>
      <geometry>
        <mesh filename="meshes/base_link/3d66-Editable_Poly-23002546-057.obj"/>
      </geometry>
      <material name="robot_gray">
        <color rgba="0.85 0.85 0.85 1.0"/>
      </material>
    </visual>
    <visual>
      <origin xyz="0 0 0" rpy="0 0 0"/>
      <geometry>
        <mesh filename="meshes/base_link/3d66-Editable_Poly-23002546-058.obj"/>
      </geometry>
      <material name="robot_gray">
        <color rgba="0.85 0.85 0.85 1.0"/>
      </material>
    </visual>
    <visual>
      <origin xyz="0 0 0" rpy="0 0 0"/>
      <geometry>
        <mesh filename="meshes/base_link/3d66-Editable_Poly-23002546-059.obj"/>
      </geometry>
      <material name="robot_gray">
        <color rgba="0.85 0.85 0.85 1.0"/>
      </material>
    </visual>
    <visual>
      <origin xyz="0 0 0" rpy="0 0 0"/>
      <geometry>
        <mesh filename="meshes/base_link/3d66-Editable_Poly-23002546-060.obj"/>
      </geometry>
      <material name="robot_gray">
        <color rgba="0.85 0.85 0.85 1.0"/>
      </material>
    </visual>
    <visual>
      <origin xyz="0 0 0" rpy="0 0 0"/>
      <geometry>
        <mesh filename="meshes/base_link/3d66-Editable_Poly-23002546-061.obj"/>
      </geometry>
      <material name="robot_gray">
        <color rgba="0.85 0.85 0.85 1.0"/>
      </material>
    </visual>
    <visual>
      <origin xyz="0 0 0" rpy="0 0 0"/>
      <geometry>
        <mesh filename="meshes/base_link/3d66-Editable_Poly-23002546-062.obj"/>
      </geometry>
      <material name="robot_gray">
        <color rgba="0.85 0.85 0.85 1.0"/>
      </material>
    </visual>
    <visual>
      <origin xyz="0 0 0" rpy="0 0 0"/>
      <geometry>
        <mesh filename="meshes/base_link/3d66-Editable_Poly-23002546-063.obj"/>
      </geometry>
      <material name="robot_gray">
        <color rgba="0.85 0.85 0.85 1.0"/>
      </material>
    </visual>
    <visual>
      <origin xyz="0 0 0" rpy="0 0 0"/>
      <geometry>
        <mesh filename="meshes/base_link/3d66-Editable_Poly-23002546-064.obj"/>
      </geometry>
      <material name="robot_gray">
        <color rgba="0.85 0.85 0.85 1.0"/>
      </material>
    </visual>
    <visual>
      <origin xyz="0 0 0" rpy="0 0 0"/>
      <geometry>
        <mesh filename="meshes/base_link/3d66-Editable_Poly-23002546-065.obj"/>
      </geometry>
      <material name="robot_gray">
        <color rgba="0.85 0.85 0.85 1.0"/>
      </material>
    </visual>
    <visual>
      <origin xyz="0 0 0" rpy="0 0 0"/>
      <geometry>
        <mesh filename="meshes/base_link/3d66-Editable_Poly-23002546-066.obj"/>
      </geometry>
      <material name="robot_gray">
        <color rgba="0.85 0.85 0.85 1.0"/>
      </material>
    </visual>
    <visual>
      <origin xyz="0 0 0" rpy="0 0 0"/>
      <geometry>
        <mesh filename="meshes/base_link/3d66-Editable_Poly-23002546-070.obj"/>
      </geometry>
      <material name="robot_gray">
        <color rgba="0.85 0.85 0.85 1.0"/>
      </material>
    </visual>
    <visual>
      <origin xyz="0 0 0" rpy="0 0 0"/>
      <geometry>
        <mesh filename="meshes/base_link/3d66-PolyMeshObject-23002546-017.obj"/>
      </geometry>
      <material name="robot_gray">
        <color rgba="0.85 0.85 0.85 1.0"/>
      </material>
    </visual>
    <visual>
      <origin xyz="0 0 0" rpy="0 0 0"/>
      <geometry>
        <mesh filename="meshes/base_link/3d66-PolyMeshObject-23002546-018.obj"/>
      </geometry>
      <material name="robot_gray">
        <color rgba="0.85 0.85 0.85 1.0"/>
      </material>
    </visual>
    <visual>
      <origin xyz="0 0 0" rpy="0 0 0"/>
      <geometry>
        <mesh filename="meshes/base_link/3d66-PolyMeshObject-23002546-019.obj"/>
      </geometry>
      <material name="robot_gray">
        <color rgba="0.85 0.85 0.85 1.0"/>
      </material>
    </visual>
    <visual>
      <origin xyz="0 0 0" rpy="0 0 0"/>
      <geometry>
        <mesh filename="meshes/base_link/3d66-PolyMeshObject-23002546-020.obj"/>
      </geometry>
      <material name="robot_gray">
        <color rgba="0.85 0.85 0.85 1.0"/>
      </material>
    </visual>
    <visual>
      <origin xyz="0 0 0" rpy="0 0 0"/>
      <geometry>
        <mesh filename="meshes/base_link/3d66-PolyMeshObject-23002546-021.obj"/>
      </geometry>
      <material name="robot_gray">
        <color rgba="0.85 0.85 0.85 1.0"/>
      </material>
    </visual>
    <visual>
      <origin xyz="0 0 0" rpy="0 0 0"/>
      <geometry>
        <mesh filename="meshes/base_link/3d66-PolyMeshObject-23002546-022.obj"/>
      </geometry>
      <material name="robot_gray">
        <color rgba="0.85 0.85 0.85 1.0"/>
      </material>
    </visual>
    <visual>
      <origin xyz="0 0 0" rpy="0 0 0"/>
      <geometry>
        <mesh filename="meshes/base_link/3d66-PolyMeshObject-23002546-023.obj"/>
      </geometry>
      <material name="robot_gray">
        <color rgba="0.85 0.85 0.85 1.0"/>
      </material>
    </visual>
    <visual>
      <origin xyz="0 0 0" rpy="0 0 0"/>
      <geometry>
        <mesh filename="meshes/base_link/3d66-PolyMeshObject-23002546-024.obj"/>
      </geometry>
      <material name="robot_gray">
        <color rgba="0.85 0.85 0.85 1.0"/>
      </material>
    </visual>
    <visual>
      <origin xyz="0 0 0" rpy="0 0 0"/>
      <geometry>
        <mesh filename="meshes/base_link/3d66-PolyMeshObject-23002546-025.obj"/>
      </geometry>
      <material name="robot_gray">
        <color rgba="0.85 0.85 0.85 1.0"/>
      </material>
    </visual>
    <visual>
      <origin xyz="0 0 0" rpy="0 0 0"/>
      <geometry>
        <mesh filename="meshes/base_link/3d66-PolyMeshObject-23002546-026.obj"/>
      </geometry>
      <material name="robot_gray">
        <color rgba="0.85 0.85 0.85 1.0"/>
      </material>
    </visual>
    <visual>
      <origin xyz="0 0 0" rpy="0 0 0"/>
      <geometry>
        <mesh filename="meshes/base_link/3d66-PolyMeshObject-23002546-027.obj"/>
      </geometry>
      <material name="robot_gray">
        <color rgba="0.85 0.85 0.85 1.0"/>
      </material>
    </visual>
  </link>
  <link name="yaw_link">
    <inertial>
      <origin xyz="0 0 0" rpy="0 0 0"/>
      <mass value="0.200000"/>
      <inertia ixx="0.001" ixy="0" ixz="0" iyy="0.001" iyz="0" izz="0.001"/>
    </inertial>
    <visual>
      <origin xyz="0 0 0" rpy="0 0 0"/>
      <geometry>
        <mesh filename="meshes/yaw_link/3d66-Editable_Poly-23002546-044.obj"/>
      </geometry>
      <material name="robot_gray">
        <color rgba="0.85 0.85 0.85 1.0"/>
      </material>
    </visual>
    <visual>
      <origin xyz="0 0 0" rpy="0 0 0"/>
      <geometry>
        <mesh filename="meshes/yaw_link/3d66-Editable_Poly-23002546-045.obj"/>
      </geometry>
      <material name="robot_gray">
        <color rgba="0.85 0.85 0.85 1.0"/>
      </material>
    </visual>
    <visual>
      <origin xyz="0 0 0" rpy="0 0 0"/>
      <geometry>
        <mesh filename="meshes/yaw_link/3d66-Editable_Poly-23002546-046.obj"/>
      </geometry>
      <material name="robot_gray">
        <color rgba="0.85 0.85 0.85 1.0"/>
      </material>
    </visual>
    <visual>
      <origin xyz="0 0 0" rpy="0 0 0"/>
      <geometry>
        <mesh filename="meshes/yaw_link/3d66-Editable_Poly-23002546-047.obj"/>
      </geometry>
      <material name="robot_gray">
        <color rgba="0.85 0.85 0.85 1.0"/>
      </material>
    </visual>
    <visual>
      <origin xyz="0 0 0" rpy="0 0 0"/>
      <geometry>
        <mesh filename="meshes/yaw_link/3d66-Editable_Poly-23002546-048.obj"/>
      </geometry>
      <material name="robot_gray">
        <color rgba="0.85 0.85 0.85 1.0"/>
      </material>
    </visual>
    <visual>
      <origin xyz="0 0 0" rpy="0 0 0"/>
      <geometry>
        <mesh filename="meshes/yaw_link/3d66-Editable_Poly-23002546-049.obj"/>
      </geometry>
      <material name="robot_gray">
        <color rgba="0.85 0.85 0.85 1.0"/>
      </material>
    </visual>
  </link>
  <link name="boom1_link">
    <inertial>
      <origin xyz="0 0 0" rpy="0 0 0"/>
      <mass value="2.000000"/>
      <inertia ixx="0.001" ixy="0" ixz="0" iyy="0.001" iyz="0" izz="0.001"/>
    </inertial>
    <visual>
      <origin xyz="0 0 0" rpy="0 0 0"/>
      <geometry>
        <mesh filename="meshes/boom1_link/3d66-Editable_Poly-23002546-050.obj"/>
      </geometry>
      <material name="robot_gray">
        <color rgba="0.85 0.85 0.85 1.0"/>
      </material>
    </visual>
    <visual>
      <origin xyz="0 0 0" rpy="0 0 0"/>
      <geometry>
        <mesh filename="meshes/boom1_link/3d66-Editable_Poly-23002546-054.obj"/>
      </geometry>
      <material name="robot_gray">
        <color rgba="0.85 0.85 0.85 1.0"/>
      </material>
    </visual>
    <visual>
      <origin xyz="0 0 0" rpy="0 0 0"/>
      <geometry>
        <mesh filename="meshes/boom1_link/3d66-Editable_Poly-23002546-067.obj"/>
      </geometry>
      <material name="robot_gray">
        <color rgba="0.85 0.85 0.85 1.0"/>
      </material>
    </visual>
    <visual>
      <origin xyz="0 0 0" rpy="0 0 0"/>
      <geometry>
        <mesh filename="meshes/boom1_link/3d66-Editable_Poly-23002546-055.obj"/>
      </geometry>
      <material name="robot_gray">
        <color rgba="0.85 0.85 0.85 1.0"/>
      </material>
    </visual>
    <visual>
      <origin xyz="0 0 0" rpy="0 0 0"/>
      <geometry>
        <mesh filename="meshes/boom1_link/3d66-Editable_Poly-23002546-068.obj"/>
      </geometry>
      <material name="robot_gray">
        <color rgba="0.85 0.85 0.85 1.0"/>
      </material>
    </visual>
  </link>
  <link name="boom2_link">
    <inertial>
      <origin xyz="0 0 0" rpy="0 0 0"/>
      <mass value="1.000000"/>
      <inertia ixx="0.001" ixy="0" ixz="0" iyy="0.001" iyz="0" izz="0.001"/>
    </inertial>
    <visual>
      <origin xyz="0 0 0" rpy="0 0 0"/>
      <geometry>
        <mesh filename="meshes/boom2_link/3d66-Editable_Poly-23002546-051.obj"/>
      </geometry>
      <material name="robot_gray">
        <color rgba="0.85 0.85 0.85 1.0"/>
      </material>
    </visual>
    <visual>
      <origin xyz="0 0 0" rpy="0 0 0"/>
      <geometry>
        <mesh filename="meshes/boom2_link/3d66-Editable_Poly-23002546-056.obj"/>
      </geometry>
      <material name="robot_gray">
        <color rgba="0.85 0.85 0.85 1.0"/>
      </material>
    </visual>
    <visual>
      <origin xyz="0 0 0" rpy="0 0 0"/>
      <geometry>
        <mesh filename="meshes/boom2_link/3d66-Editable_Poly-23002546-069.obj"/>
      </geometry>
      <material name="robot_gray">
        <color rgba="0.85 0.85 0.85 1.0"/>
      </material>
    </visual>
  </link>
  <link name="boom3_link">
    <inertial>
      <origin xyz="0 0 0" rpy="0 0 0"/>
      <mass value="1.000000"/>
      <inertia ixx="0.001" ixy="0" ixz="0" iyy="0.001" iyz="0" izz="0.001"/>
    </inertial>
    <visual>
      <origin xyz="0 0 0" rpy="0 0 0"/>
      <geometry>
        <mesh filename="meshes/boom3_link/3d66-Editable_Poly-23002546-052.obj"/>
      </geometry>
      <material name="robot_gray">
        <color rgba="0.85 0.85 0.85 1.0"/>
      </material>
    </visual>
  </link>
  <joint name="turret_yaw" type="revolute">
    <parent link="base_link"/>
    <child link="yaw_link"/>
    <origin xyz="0.000000 0.000000 0.000000" rpy="0 0 0"/>
    <axis xyz="0 0 1"/>
    <limit lower="-1.57079633" upper="1.57079633" effort="100" velocity="2.0"/>
    <dynamics damping="0.5" friction="0.0"/>
  </joint>
  <joint name="shoulder_pitch" type="revolute">
    <parent link="yaw_link"/>
    <child link="boom1_link"/>
    <origin xyz="0.000000 -0.119299 0.082713" rpy="0 0 0"/>
    <axis xyz="-1 0 0"/>
    <limit lower="-0.34906585" upper="1.04719755" effort="80" velocity="2.0"/>
    <dynamics damping="0.5" friction="0.0"/>
  </joint>
  <joint name="elbow_pitch" type="revolute">
    <parent link="boom1_link"/>
    <child link="boom2_link"/>
    <origin xyz="0.000000 -0.909985 0.625785" rpy="0 0 0"/>
    <axis xyz="-1 0 0"/>
    <limit lower="-1.74532925" upper="1.74532925" effort="60" velocity="2.0"/>
    <dynamics damping="0.5" friction="0.0"/>
  </joint>
  <joint name="wrist_pitch" type="revolute">
    <parent link="boom2_link"/>
    <child link="boom3_link"/>
    <origin xyz="0.000000 -0.726177 -0.420024" rpy="0 0 0"/>
    <axis xyz="-1 0 0"/>
    <limit lower="-1.91986218" upper="1.22173048" effort="40" velocity="2.0"/>
    <dynamics damping="0.5" friction="0.0"/>
  </joint>
</robot>
